const x = 10;

try {
  x = 2;
} catch (err) {
  console.log(`Erro: Não foi possível continuar`);
}
